<?xml version="1.0"?>
<robot name="simple_amr" xmlns:xacro="http://www.ros.org/wiki/xacro">

  <link name="main_base"/>

  <joint name="base_footprint_joint" type="fixed">
    <parent link="main_base"/>
    <child link="base_footprint"/>
    <origin xyz="0 0 0" rpy="0 0 0"/>
  </joint>

  <link name="base_footprint"/>

  <link name="base_link">
    <visual>
      <geometry>
        <box size="0.6 0.4 0.2"/>
      </geometry>
      <origin xyz="0 0 0.1" rpy="0 0 0"/>
      <material name="gray">
        <color rgba="0.5 0.5 0.5 1"/>
      </material>
    </visual>
    <collision>
      <geometry>
        <box size="0.6 0.4 0.2"/>
      </geometry>
      <origin xyz="0 0 0.1" rpy="0 0 0"/>
    </collision>
    <inertial>
      <mass value="5"/>
      <inertia ixx="0.1" iyy="0.1" izz="0.1" ixy="0.0" ixz="0.0" iyz="0.0"/>
    </inertial>
  </link>

  <link name="left_wheel">
    <visual>
      <geometry>
        <cylinder length="0.05" radius="0.1"/>
      </geometry>
      <origin xyz="0 0 0" rpy="1.5708 0 0"/>
      <material name="black">
        <color rgba="0 0 0 1"/>
      </material>
    </visual>
    <collision>
      <geometry>
        <cylinder length="0.05" radius="0.1"/>
      </geometry>
      <origin xyz="0 0 0" rpy="1.5708 0 0"/>
    </collision>
    <inertial>
      <mass value="1"/>
      <inertia ixx="0.01" iyy="0.01" izz="0.01" ixy="0.0" ixz="0.0" iyz="0.0"/>
    </inertial>
  </link>

  <link name="right_wheel">
    <visual>
      <geometry>
        <cylinder length="0.05" radius="0.1"/>
      </geometry>
      <origin xyz="0 0 0" rpy="1.5708 0 0"/>
      <material name="black"/>
    </visual>
    <collision>
      <geometry>
        <cylinder length="0.05" radius="0.1"/>
      </geometry>
      <origin xyz="0 0 0" rpy="1.5708 0 0"/>
    </collision>
    <inertial>
      <mass value="1"/>
      <inertia ixx="0.01" iyy="0.01" izz="0.01" ixy="0.0" ixz="0.0" iyz="0.0"/>
    </inertial>
  </link>

  <link name="stability_wheel">
    <visual>
      <geometry>
        <sphere radius="0.05"/>
      </geometry>
      <origin xyz="0 0 0" rpy="0 0 0"/>
      <material name="black"/>
    </visual>
    <collision>
      <geometry>
        <sphere radius="0.05"/>
      </geometry>
      <origin xyz="0 0 0" rpy="0 0 0"/>
    </collision>
    <inertial>
      <mass value="1"/>
      <inertia ixx="0.001" iyy="0.001" izz="0.001" ixy="0.0" ixz="0.0" iyz="0.0"/>
    </inertial>
  </link>

  <link name="Lidar_link">
    <visual>
      <geometry>
        <cylinder length="0.05" radius="0.03"/> 
      </geometry>
      <origin xyz="0 0 0" rpy="0 0 0"/>
      <material name="red">
        <color rgba="1 0 0 1"/>
      </material>
    </visual>
    <collision>
      <geometry>
        <cylinder length="0.05" radius="0.03"/> 
      </geometry>
      <origin xyz="0 0 0" rpy="0 0 0"/>
    </collision>
    <inertial>
      <mass value="1"/>
      <inertia ixx="0.001" iyy="0.001" izz="0.001" ixy="0.0" ixz="0.0" iyz="0.0"/>
    </inertial>
  </link>

  <joint name="base_joint" type="fixed">
    <parent link="main_base"/>
    <child link="base_link"/>
    <origin xyz="0 0 0.1" rpy="0 0 0"/>
  </joint>

  <joint name="left_wheel_joint" type="continuous">
    <parent link="base_link"/>
    <child link="left_wheel"/>
    <origin xyz="-0.15 0.225 0" rpy="0 0 0"/>
    <axis xyz="0 1 0"/>
  </joint>

  <joint name="right_wheel_joint" type="continuous">
    <parent link="base_link"/>
    <child link="right_wheel"/>
    <origin xyz="-0.15 -0.225 0" rpy="0 0 0"/>
    <axis xyz="0 1 0"/>
  </joint>

  <joint name="stability_wheel_joint" type="fixed">
    <parent link="base_link"/>
    <child link="stability_wheel"/>
    <origin xyz="0.2 0 -0.05" rpy="0 0 0"/>
  </joint>

  <joint name="Lidar_joint" type="fixed">
    <parent link="base_link"/>
    <child link="Lidar_link"/>
    <origin xyz="0.2 0 0.225" rpy="0 0 0"/>
  </joint>

  <gazebo reference="left_wheel">
    <mu1 value="0.5"/>
    <mu2 value="0.5"/>
    <kp value="1000000.0" />
    <kd value="10.0" />
  </gazebo>

  <gazebo reference="right_wheel">
    <mu1 value="0.5"/>
    <mu2 value="0.5"/>
    <kp value="1000000.0" />
    <kd value="10.0" />
  </gazebo>

  <gazebo reference="stability_wheel">
    <mu1 value="0.001"/>
    <mu2 value="0.001"/>
  </gazebo>

  <gazebo>
    <plugin name="diff_drive" filename="libgazebo_ros_diff_drive.so">
      <ros>
        <remapping>cmd_vel:=cmd_vel</remapping>
      </ros>
      <left_joint>left_wheel_joint</left_joint>
      <right_joint>right_wheel_joint</right_joint>
      <wheel_separation>0.45</wheel_separation>
      <wheel_diameter>0.2</wheel_diameter>

      <odomentry_frame>odom</odomentry_frame>
      <robot_base_frame>main_base</robot_base_frame>
      <publish_odom>true</publish_odom>
      <publish_odom_tf>true</publish_odom_tf>
      <publish_wheel_tf>true</publish_wheel_tf>
    </plugin>
  </gazebo>

  <gazebo reference="Lidar_link">
    <sensor name="laser" type="ray">
      <pose> 0 0 0 0 0 0 </pose>
      <visualize>true</visualize>
      <update_rate>10</update_rate>
      <ray>
        <scan>
          <horizontal>
            <samples>360</samples>
            <resolution>1</resolution>
            <min_angle>-3.14</min_angle>
            <max_angle>3.14</max_angle>
          </horizontal>
        </scan>
        <range>
          <min>0.3</min>
          <max>12</max>
          <resolution>0.01</resolution>
        </range>
      </ray>
      <plugin name="laser_controller" filename="libgazebo_ros_ray_sensor.so">
        <ros>
          <remapping>~/out:=scan</remapping>
        </ros>
        <output_type>sensor_msgs/LaserScan</output_type>
        <frame_name>Lidar_link</frame_name>
      </plugin>
    </sensor>
  </gazebo>

</robot>